<!DOCTYPE html>
<html xmlns="http://www.w3.org/1999/xhtml" lang="" xml:lang="">
<head>
  <meta charset="utf-8" />
  <meta name="generator" content="pandoc" />
  <meta name="viewport" content="width=device-width, initial-scale=1.0, user-scalable=yes" />
  <title>solution</title>
  <style type="text/css">
      code{white-space: pre-wrap;}
      span.smallcaps{font-variant: small-caps;}
      span.underline{text-decoration: underline;}
      div.column{display: inline-block; vertical-align: top; width: 50%;}
  </style>
</head>
<body>
<p>The answer is: <strong>no, it won’t</strong>:</p>
<p><code>js run new Promise(function(resolve, reject) {   setTimeout(() =&gt; {     throw new Error("Whoops!");   }, 1000); }).catch(alert);</code></p>
<p>As said in the chapter, there’s an “implicit <code>try..catch</code>” around the function code. So all synchronous errors are handled.</p>
<p>But here the error is generated not while the executor is running, but later. So the promise can’t handle it.</p>
</body>
</html>
