<!DOCTYPE html>
<html xmlns="http://www.w3.org/1999/xhtml" lang="" xml:lang="">
<head>
  <meta charset="utf-8" />
  <meta name="generator" content="pandoc" />
  <meta name="viewport" content="width=device-width, initial-scale=1.0, user-scalable=yes" />
  <title>article</title>
  <style type="text/css">
      code{white-space: pre-wrap;}
      span.smallcaps{font-variant: small-caps;}
      span.underline{text-decoration: underline;}
      div.column{display: inline-block; vertical-align: top; width: 50%;}
  </style>
  <style type="text/css">
a.sourceLine { display: inline-block; line-height: 1.25; }
a.sourceLine { pointer-events: none; color: inherit; text-decoration: inherit; }
a.sourceLine:empty { height: 1.2em; }
.sourceCode { overflow: visible; }
code.sourceCode { white-space: pre; position: relative; }
div.sourceCode { margin: 1em 0; }
pre.sourceCode { margin: 0; }
@media screen {
div.sourceCode { overflow: auto; }
}
@media print {
code.sourceCode { white-space: pre-wrap; }
a.sourceLine { text-indent: -1em; padding-left: 1em; }
}
pre.numberSource a.sourceLine
  { position: relative; left: -4em; }
pre.numberSource a.sourceLine::before
  { content: attr(title);
    position: relative; left: -1em; text-align: right; vertical-align: baseline;
    border: none; pointer-events: all; display: inline-block;
    -webkit-touch-callout: none; -webkit-user-select: none;
    -khtml-user-select: none; -moz-user-select: none;
    -ms-user-select: none; user-select: none;
    padding: 0 4px; width: 4em;
    color: #aaaaaa;
  }
pre.numberSource { margin-left: 3em; border-left: 1px solid #aaaaaa;  padding-left: 4px; }
div.sourceCode
  {  }
@media screen {
a.sourceLine::before { text-decoration: underline; }
}
code span.al { color: #ff0000; font-weight: bold; } /* Alert */
code span.an { color: #60a0b0; font-weight: bold; font-style: italic; } /* Annotation */
code span.at { color: #7d9029; } /* Attribute */
code span.bn { color: #40a070; } /* BaseN */
code span.bu { } /* BuiltIn */
code span.cf { color: #007020; font-weight: bold; } /* ControlFlow */
code span.ch { color: #4070a0; } /* Char */
code span.cn { color: #880000; } /* Constant */
code span.co { color: #60a0b0; font-style: italic; } /* Comment */
code span.cv { color: #60a0b0; font-weight: bold; font-style: italic; } /* CommentVar */
code span.do { color: #ba2121; font-style: italic; } /* Documentation */
code span.dt { color: #902000; } /* DataType */
code span.dv { color: #40a070; } /* DecVal */
code span.er { color: #ff0000; font-weight: bold; } /* Error */
code span.ex { } /* Extension */
code span.fl { color: #40a070; } /* Float */
code span.fu { color: #06287e; } /* Function */
code span.im { } /* Import */
code span.in { color: #60a0b0; font-weight: bold; font-style: italic; } /* Information */
code span.kw { color: #007020; font-weight: bold; } /* Keyword */
code span.op { color: #666666; } /* Operator */
code span.ot { color: #007020; } /* Other */
code span.pp { color: #bc7a00; } /* Preprocessor */
code span.sc { color: #4070a0; } /* SpecialChar */
code span.ss { color: #bb6688; } /* SpecialString */
code span.st { color: #4070a0; } /* String */
code span.va { color: #19177c; } /* Variable */
code span.vs { color: #4070a0; } /* VerbatimString */
code span.wa { color: #60a0b0; font-weight: bold; font-style: italic; } /* Warning */
  </style>
</head>
<body>
<h1 id="error-handling-trycatch">Error handling, “try…catch”</h1>
<p>No matter how great we are at programming, sometimes our scripts have errors. They may occur because of our mistakes, an unexpected user input, an erroneous server response, and for a thousand other reasons.</p>
<p>Usually, a script “dies” (immediately stops) in case of an error, printing it to console.</p>
<p>But there’s a syntax construct <code>try...catch</code> that allows us to “catch” errors so the script can, instead of dying, do something more reasonable.</p>
<h2 id="the-trycatch-syntax">The “try…catch” syntax</h2>
<p>The <code>try...catch</code> construct has two main blocks: <code>try</code>, and then <code>catch</code>:</p>
<div class="sourceCode" id="cb1"><pre class="sourceCode js"><code class="sourceCode javascript"><a class="sourceLine" id="cb1-1" title="1"><span class="cf">try</span> <span class="op">{</span></a>
<a class="sourceLine" id="cb1-2" title="2"></a>
<a class="sourceLine" id="cb1-3" title="3">  <span class="co">// code...</span></a>
<a class="sourceLine" id="cb1-4" title="4"></a>
<a class="sourceLine" id="cb1-5" title="5"><span class="op">}</span> <span class="cf">catch</span> (err) <span class="op">{</span></a>
<a class="sourceLine" id="cb1-6" title="6"></a>
<a class="sourceLine" id="cb1-7" title="7">  <span class="co">// error handling</span></a>
<a class="sourceLine" id="cb1-8" title="8"></a>
<a class="sourceLine" id="cb1-9" title="9"><span class="op">}</span></a></code></pre></div>
<p>It works like this:</p>
<ol type="1">
<li>First, the code in <code>try {...}</code> is executed.</li>
<li>If there were no errors, then <code>catch (err)</code> is ignored: the execution reaches the end of <code>try</code> and goes on, skipping <code>catch</code>.</li>
<li>If an error occurs, then the <code>try</code> execution is stopped, and control flows to the beginning of <code>catch (err)</code>. The <code>err</code> variable (we can use any name for it) will contain an error object with details about what happened.</li>
</ol>
<p><img src="try-catch-flow.svg" /></p>
<p>So, an error inside the <code>try {...}</code> block does not kill the script – we have a chance to handle it in <code>catch</code>.</p>
<p>Let’s look at some examples.</p>
<ul>
<li><p>An errorless example: shows <code>alert</code> <code>(1)</code> and <code>(2)</code>:</p>
<p>```js run try {</p>
<pre><code>alert(&#39;Start of try runs&#39;);  // *!*(1) &lt;--*/!*

// ...no errors here

alert(&#39;End of try runs&#39;);   // *!*(2) &lt;--*/!*</code></pre>
<p>} catch (err) {</p>
<pre><code>alert(&#39;Catch is ignored, because there are no errors&#39;); // (3)</code></pre>
} ```</li>
<li><p>An example with an error: shows <code>(1)</code> and <code>(3)</code>:</p>
<p>```js run try {</p>
<pre><code>alert(&#39;Start of try runs&#39;);  // *!*(1) &lt;--*/!*</code></pre>
<p><em>!</em> lalala; // error, variable is not defined! <em>/!</em></p>
<pre><code>alert(&#39;End of try (never reached)&#39;);  // (2)</code></pre>
<p>} catch (err) {</p>
<pre><code>alert(`Error has occurred!`); // *!*(3) &lt;--*/!*</code></pre>
<p>} ```</p></li>
</ul>
<p>```<code>warn header="</code>try…catch<code>only works for runtime errors" For</code>try…catch` to work, the code must be runnable. In other words, it should be valid JavaScript.</p>
<p>It won’t work if the code is syntactically wrong, for instance it has unmatched curly braces:</p>
<p><code>js run try {   {{{{{{{{{{{{ } catch (err) {   alert("The engine can't understand this code, it's invalid"); }</code></p>
<p>The JavaScript engine first reads the code, and then runs it. The errors that occur on the reading phase are called “parse-time” errors and are unrecoverable (from inside that code). That’s because the engine can’t understand the code.</p>
<p>So, <code>try...catch</code> can only handle errors that occur in valid code. Such errors are called “runtime errors” or, sometimes, “exceptions”. ````</p>
<p>```<code>warn header="</code>try…catch<code>works synchronously" If an exception happens in "scheduled" code, like in</code>setTimeout<code>, then</code>try…catch` won’t catch it:</p>
<p><code>js run try {   setTimeout(function() {     noSuchVariable; // script will die here   }, 1000); } catch (err) {   alert( "won't work" ); }</code></p>
<p>That’s because the function itself is executed later, when the engine has already left the <code>try...catch</code> construct.</p>
<p>To catch an exception inside a scheduled function, <code>try...catch</code> must be inside that function: <code>js run setTimeout(function() {   try {         noSuchVariable; // try...catch handles the error!   } catch {     alert( "error is caught here!" );   } }, 1000);</code> ````</p>
<h2 id="error-object">Error object</h2>
<p>When an error occurs, JavaScript generates an object containing the details about it. The object is then passed as an argument to <code>catch</code>:</p>
<div class="sourceCode" id="cb7"><pre class="sourceCode js"><code class="sourceCode javascript"><a class="sourceLine" id="cb7-1" title="1"><span class="cf">try</span> <span class="op">{</span></a>
<a class="sourceLine" id="cb7-2" title="2">  <span class="co">// ...</span></a>
<a class="sourceLine" id="cb7-3" title="3"><span class="op">}</span> <span class="cf">catch</span> (err) <span class="op">{</span> <span class="co">// &lt;-- the &quot;error object&quot;, could use another word instead of err</span></a>
<a class="sourceLine" id="cb7-4" title="4">  <span class="co">// ...</span></a>
<a class="sourceLine" id="cb7-5" title="5"><span class="op">}</span></a></code></pre></div>
<p>For all built-in errors, the error object has two main properties:</p>
<dl>
<dt><code>name</code></dt>
<dd>Error name. For instance, for an undefined variable that’s <code>"ReferenceError"</code>.
</dd>
<dt><code>message</code></dt>
<dd>Textual message about error details.
</dd>
</dl>
<p>There are other non-standard properties available in most environments. One of most widely used and supported is:</p>
<dl>
<dt><code>stack</code></dt>
<dd>Current call stack: a string with information about the sequence of nested calls that led to the error. Used for debugging purposes.
</dd>
</dl>
<p>For instance:</p>
<p>```js run untrusted try { <em>!</em> lalala; // error, variable is not defined! <em>/!</em> } catch (err) { alert(err.name); // ReferenceError alert(err.message); // lalala is not defined alert(err.stack); // ReferenceError: lalala is not defined at (…call stack)</p>
<p>// Can also show an error as a whole // The error is converted to string as “name: message” alert(err); // ReferenceError: lalala is not defined } ```</p>
<h2 id="optional-catch-binding">Optional “catch” binding</h2>
<p>[recent browser=new]</p>
<p>If we don’t need error details, <code>catch</code> may omit it:</p>
<div class="sourceCode" id="cb8"><pre class="sourceCode js"><code class="sourceCode javascript"><a class="sourceLine" id="cb8-1" title="1"><span class="cf">try</span> <span class="op">{</span></a>
<a class="sourceLine" id="cb8-2" title="2">  <span class="co">// ...</span></a>
<a class="sourceLine" id="cb8-3" title="3"><span class="op">}</span> <span class="cf">catch</span> <span class="op">{</span> <span class="co">// &lt;-- without (err)</span></a>
<a class="sourceLine" id="cb8-4" title="4">  <span class="co">// ...</span></a>
<a class="sourceLine" id="cb8-5" title="5"><span class="op">}</span></a></code></pre></div>
<h2 id="using-trycatch">Using “try…catch”</h2>
<p>Let’s explore a real-life use case of <code>try...catch</code>.</p>
<p>As we already know, JavaScript supports the <a href="mdn:js/JSON/parse">JSON.parse(str)</a> method to read JSON-encoded values.</p>
<p>Usually it’s used to decode data received over the network, from the server or another source.</p>
<p>We receive it and call <code>JSON.parse</code> like this:</p>
<p>```js run let json = ‘{“name”:“John”, “age”: 30}’; // data from the server</p>
<p><em>!</em> let user = JSON.parse(json); // convert the text representation to JS object <em>/!</em></p>
<p>// now user is an object with properties from the string alert( user.name ); // John alert( user.age ); // 30 ```</p>
<p>You can find more detailed information about JSON in the <a href="info:json" class="uri">info:json</a> chapter.</p>
<p><strong>If <code>json</code> is malformed, <code>JSON.parse</code> generates an error, so the script “dies”.</strong></p>
<p>Should we be satisfied with that? Of course not!</p>
<p>This way, if something’s wrong with the data, the visitor will never know that (unless they open the developer console). And people really don’t like when something “just dies” without any error message.</p>
<p>Let’s use <code>try...catch</code> to handle the error:</p>
<p>```js run let json = “{ bad json }”;</p>
<p>try {</p>
<p><em>!</em> let user = JSON.parse(json); // &lt;– when an error occurs… <em>/!</em> alert( user.name ); // doesn’t work</p>
<p>} catch (err) { <em>!</em> // …the execution jumps here alert( “Our apologies, the data has errors, we’ll try to request it one more time.” ); alert( err.name ); alert( err.message ); <em>/!</em> } ```</p>
<p>Here we use the <code>catch</code> block only to show the message, but we can do much more: send a new network request, suggest an alternative to the visitor, send information about the error to a logging facility, … . All much better than just dying.</p>
<h2 id="throwing-our-own-errors">Throwing our own errors</h2>
<p>What if <code>json</code> is syntactically correct, but doesn’t have a required <code>name</code> property?</p>
<p>Like this:</p>
<p>```js run let json = ‘{ “age”: 30 }’; // incomplete data</p>
<p>try {</p>
<p>let user = JSON.parse(json); // &lt;– no errors <em>!</em> alert( user.name ); // no name! <em>/!</em></p>
<p>} catch (err) { alert( “doesn’t execute” ); } ```</p>
<p>Here <code>JSON.parse</code> runs normally, but the absence of <code>name</code> is actually an error for us.</p>
<p>To unify error handling, we’ll use the <code>throw</code> operator.</p>
<h3 id="throw-operator">“Throw” operator</h3>
<p>The <code>throw</code> operator generates an error.</p>
<p>The syntax is:</p>
<div class="sourceCode" id="cb9"><pre class="sourceCode js"><code class="sourceCode javascript"><a class="sourceLine" id="cb9-1" title="1"><span class="cf">throw</span> <span class="op">&lt;</span>error object<span class="op">&gt;</span></a></code></pre></div>
<p>Technically, we can use anything as an error object. That may be even a primitive, like a number or a string, but it’s better to use objects, preferably with <code>name</code> and <code>message</code> properties (to stay somewhat compatible with built-in errors).</p>
<p>JavaScript has many built-in constructors for standard errors: <code>Error</code>, <code>SyntaxError</code>, <code>ReferenceError</code>, <code>TypeError</code> and others. We can use them to create error objects as well.</p>
<p>Their syntax is:</p>
<div class="sourceCode" id="cb10"><pre class="sourceCode js"><code class="sourceCode javascript"><a class="sourceLine" id="cb10-1" title="1"><span class="kw">let</span> error <span class="op">=</span> <span class="kw">new</span> <span class="at">Error</span>(message)<span class="op">;</span></a>
<a class="sourceLine" id="cb10-2" title="2"><span class="co">// or</span></a>
<a class="sourceLine" id="cb10-3" title="3"><span class="kw">let</span> error <span class="op">=</span> <span class="kw">new</span> <span class="at">SyntaxError</span>(message)<span class="op">;</span></a>
<a class="sourceLine" id="cb10-4" title="4"><span class="kw">let</span> error <span class="op">=</span> <span class="kw">new</span> <span class="at">ReferenceError</span>(message)<span class="op">;</span></a>
<a class="sourceLine" id="cb10-5" title="5"><span class="co">// ...</span></a></code></pre></div>
<p>For built-in errors (not for any objects, just for errors), the <code>name</code> property is exactly the name of the constructor. And <code>message</code> is taken from the argument.</p>
<p>For instance:</p>
<p>```js run let error = new Error(“Things happen o_O”);</p>
<p>alert(error.name); // Error alert(error.message); // Things happen o_O ```</p>
<p>Let’s see what kind of error <code>JSON.parse</code> generates:</p>
<p><code>js run try {   JSON.parse("{ bad json o_O }"); } catch (err) { *!*   alert(err.name); // SyntaxError */!*   alert(err.message); // Unexpected token b in JSON at position 2 }</code></p>
<p>As we can see, that’s a <code>SyntaxError</code>.</p>
<p>And in our case, the absence of <code>name</code> is an error, as users must have a <code>name</code>.</p>
<p>So let’s throw it:</p>
<p>```js run let json = ‘{ “age”: 30 }’; // incomplete data</p>
<p>try {</p>
<p>let user = JSON.parse(json); // &lt;– no errors</p>
<p>if (!user.name) { <em>!</em> throw new SyntaxError(“Incomplete data: no name”); // (<em>) </em>/!* }</p>
<p>alert( user.name );</p>
<p>} catch (err) { alert( “JSON Error:” + err.message ); // JSON Error: Incomplete data: no name } ```</p>
<p>In the line <code>(*)</code>, the <code>throw</code> operator generates a <code>SyntaxError</code> with the given <code>message</code>, the same way as JavaScript would generate it itself. The execution of <code>try</code> immediately stops and the control flow jumps into <code>catch</code>.</p>
<p>Now <code>catch</code> became a single place for all error handling: both for <code>JSON.parse</code> and other cases.</p>
<h2 id="rethrowing">Rethrowing</h2>
<p>In the example above we use <code>try...catch</code> to handle incorrect data. But is it possible that <em>another unexpected error</em> occurs within the <code>try {...}</code> block? Like a programming error (variable is not defined) or something else, not just this “incorrect data” thing.</p>
<p>For example:</p>
<p>```js run let json = ‘{ “age”: 30 }’; // incomplete data</p>
<p>try { user = JSON.parse(json); // &lt;– forgot to put “let” before user</p>
<p>// … } catch (err) { alert(“JSON Error:” + err); // JSON Error: ReferenceError: user is not defined // (no JSON Error actually) } ```</p>
<p>Of course, everything’s possible! Programmers do make mistakes. Even in open-source utilities used by millions for decades – suddenly a bug may be discovered that leads to terrible hacks.</p>
<p>In our case, <code>try...catch</code> is placed to catch “incorrect data” errors. But by its nature, <code>catch</code> gets <em>all</em> errors from <code>try</code>. Here it gets an unexpected error, but still shows the same <code>"JSON Error"</code> message. That’s wrong and also makes the code more difficult to debug.</p>
<p>To avoid such problems, we can employ the “rethrowing” technique. The rule is simple:</p>
<p><strong>Catch should only process errors that it knows and “rethrow” all others.</strong></p>
<p>The “rethrowing” technique can be explained in more detail as:</p>
<ol type="1">
<li>Catch gets all errors.</li>
<li>In the <code>catch (err) {...}</code> block we analyze the error object <code>err</code>.</li>
<li>If we don’t know how to handle it, we do <code>throw err</code>.</li>
</ol>
<p>Usually, we can check the error type using the <code>instanceof</code> operator:</p>
<p><code>js run try {   user = { /*...*/ }; } catch (err) { *!*   if (err instanceof ReferenceError) { */!*     alert('ReferenceError'); // "ReferenceError" for accessing an undefined variable   } }</code></p>
<p>We can also get the error class name from <code>err.name</code> property. All native errors have it. Another option is to read <code>err.constructor.name</code>.</p>
<p>In the code below, we use rethrowing so that <code>catch</code> only handles <code>SyntaxError</code>:</p>
<p>```js run let json = ‘{ “age”: 30 }’; // incomplete data try {</p>
<p>let user = JSON.parse(json);</p>
<p>if (!user.name) { throw new SyntaxError(“Incomplete data: no name”); }</p>
<p><em>!</em> blabla(); // unexpected error <em>/!</em></p>
<p>alert( user.name );</p>
<p>} catch (err) {</p>
<p><em>!</em> if (err instanceof SyntaxError) { alert( “JSON Error:” + err.message ); } else { throw err; // rethrow (<em>) } </em>/!*</p>
<p>} ```</p>
<p>The error throwing on line <code>(*)</code> from inside <code>catch</code> block “falls out” of <code>try...catch</code> and can be either caught by an outer <code>try...catch</code> construct (if it exists), or it kills the script.</p>
<p>So the <code>catch</code> block actually handles only errors that it knows how to deal with and “skips” all others.</p>
<p>The example below demonstrates how such errors can be caught by one more level of <code>try...catch</code>:</p>
<p>```js run function readData() { let json = ‘{ “age”: 30 }’;</p>
<p>try { // … <em>!</em> blabla(); // error! <em>/!</em> } catch (err) { // … if (!(err instanceof SyntaxError)) { <em>!</em> throw err; // rethrow (don’t know how to deal with it) <em>/!</em> } } }</p>
<p>try { readData(); } catch (err) { <em>!</em> alert( “External catch got:” + err ); // caught it! <em>/!</em> } ```</p>
<p>Here <code>readData</code> only knows how to handle <code>SyntaxError</code>, while the outer <code>try...catch</code> knows how to handle everything.</p>
<h2 id="trycatchfinally">try…catch…finally</h2>
<p>Wait, that’s not all.</p>
<p>The <code>try...catch</code> construct may have one more code clause: <code>finally</code>.</p>
<p>If it exists, it runs in all cases:</p>
<ul>
<li>after <code>try</code>, if there were no errors,</li>
<li>after <code>catch</code>, if there were errors.</li>
</ul>
<p>The extended syntax looks like this:</p>
<div class="sourceCode" id="cb11"><pre class="sourceCode js"><code class="sourceCode javascript"><a class="sourceLine" id="cb11-1" title="1"><span class="op">*!*</span><span class="cf">try</span><span class="op">*</span><span class="ss">/!</span><span class="sc">*</span><span class="ss"> {</span></a>
<a class="sourceLine" id="cb11-2" title="2"><span class="ss">   ... try to execute the code ...</span></a>
<a class="sourceLine" id="cb11-3" title="3"><span class="ss">} </span><span class="sc">*</span><span class="ss">!</span><span class="sc">*</span><span class="ss">catch</span><span class="sc">*</span><span class="ss">/</span><span class="op">!*</span> (err) <span class="op">{</span></a>
<a class="sourceLine" id="cb11-4" title="4">   ... <span class="at">handle</span> <span class="va">errors</span> ...</a>
<a class="sourceLine" id="cb11-5" title="5"><span class="op">}</span> <span class="op">*!*</span><span class="cf">finally</span><span class="op">*</span><span class="ss">/!</span><span class="sc">*</span><span class="ss"> {</span></a>
<a class="sourceLine" id="cb11-6" title="6"><span class="ss">   ... execute always ...</span></a>
<a class="sourceLine" id="cb11-7" title="7"><span class="ss">}</span></a></code></pre></div>
<p>Try running this code:</p>
<p><code>js run try {   alert( 'try' );   if (confirm('Make an error?')) BAD_CODE(); } catch (err) {   alert( 'catch' ); } finally {   alert( 'finally' ); }</code></p>
<p>The code has two ways of execution:</p>
<ol type="1">
<li>If you answer “Yes” to “Make an error?”, then <code>try -&gt; catch -&gt; finally</code>.</li>
<li>If you say “No”, then <code>try -&gt; finally</code>.</li>
</ol>
<p>The <code>finally</code> clause is often used when we start doing something and want to finalize it in any case of outcome.</p>
<p>For instance, we want to measure the time that a Fibonacci numbers function <code>fib(n)</code> takes. Naturally, we can start measuring before it runs and finish afterwards. But what if there’s an error during the function call? In particular, the implementation of <code>fib(n)</code> in the code below returns an error for negative or non-integer numbers.</p>
<p>The <code>finally</code> clause is a great place to finish the measurements no matter what.</p>
<p>Here <code>finally</code> guarantees that the time will be measured correctly in both situations – in case of a successful execution of <code>fib</code> and in case of an error in it:</p>
<p>```js run let num = +prompt(“Enter a positive integer number?”, 35)</p>
<p>let diff, result;</p>
<p>function fib(n) { if (n &lt; 0 || Math.trunc(n) != n) { throw new Error(“Must not be negative, and also an integer.”); } return n &lt;= 1 ? n : fib(n - 1) + fib(n - 2); }</p>
<p>let start = Date.now();</p>
<p>try { result = fib(num); } catch (err) { result = 0; <em>!</em> } finally { diff = Date.now() - start; } <em>/!</em></p>
<p>alert(result || “error occurred”);</p>
<p>alert( <code>execution took ${diff}ms</code> ); ```</p>
<p>You can check by running the code with entering <code>35</code> into <code>prompt</code> – it executes normally, <code>finally</code> after <code>try</code>. And then enter <code>-1</code> – there will be an immediate error, and the execution will take <code>0ms</code>. Both measurements are done correctly.</p>
<p>In other words, the function may finish with <code>return</code> or <code>throw</code>, that doesn’t matter. The <code>finally</code> clause executes in both cases.</p>
<p>``<code>smart header="Variables are local inside</code>try…catch…finally<code>" Please note that</code>result<code>and</code>diff<code>variables in the code above are declared *before*</code>try…catch`.</p>
<p>Otherwise, if we declared <code>let</code> in <code>try</code> block, it would only be visible inside of it. ```</p>
<p>```<code>smart header="</code>finally<code>and</code>return<code>" The</code>finally<code>clause works for *any* exit from</code>try…catch<code>. That includes an explicit</code>return`.</p>
<p>In the example below, there’s a <code>return</code> in <code>try</code>. In this case, <code>finally</code> is executed just before the control returns to the outer code.</p>
<p>```js run function func() {</p>
<p>try { <em>!</em> return 1; <em>/!</em></p>
<p>} catch (err) { /* … <em>/ } finally { </em>!<em> alert( ‘finally’ ); </em>/!* } }</p>
<p>alert( func() ); // first works alert from finally, and then this one</p>
<pre><code></code></pre>
<p>```<code>smart header="</code>try…finally`"</p>
<p>The <code>try...finally</code> construct, without <code>catch</code> clause, is also useful. We apply it when we don’t want to handle errors here (let them fall through), but want to be sure that processes that we started are finalized.</p>
<div class="sourceCode" id="cb13"><pre class="sourceCode js"><code class="sourceCode javascript"><a class="sourceLine" id="cb13-1" title="1"><span class="kw">function</span> <span class="at">func</span>() <span class="op">{</span></a>
<a class="sourceLine" id="cb13-2" title="2">  <span class="co">// start doing something that needs completion (like measurements)</span></a>
<a class="sourceLine" id="cb13-3" title="3">  <span class="cf">try</span> <span class="op">{</span></a>
<a class="sourceLine" id="cb13-4" title="4">    <span class="co">// ...</span></a>
<a class="sourceLine" id="cb13-5" title="5">  <span class="op">}</span> <span class="cf">finally</span> <span class="op">{</span></a>
<a class="sourceLine" id="cb13-6" title="6">    <span class="co">// complete that thing even if all dies</span></a>
<a class="sourceLine" id="cb13-7" title="7">  <span class="op">}</span></a>
<a class="sourceLine" id="cb13-8" title="8"><span class="op">}</span></a></code></pre></div>
<p>In the code above, an error inside <code>try</code> always falls out, because there’s no <code>catch</code>. But <code>finally</code> works before the execution flow leaves the function. ````</p>
<h2 id="global-catch">Global catch</h2>
<p><code>warn header="Environment-specific" The information from this section is not a part of the core JavaScript.</code></p>
<p>Let’s imagine we’ve got a fatal error outside of <code>try...catch</code>, and the script died. Like a programming error or some other terrible thing.</p>
<p>Is there a way to react on such occurrences? We may want to log the error, show something to the user (normally they don’t see error messages), etc.</p>
<p>There is none in the specification, but environments usually provide it, because it’s really useful. For instance, Node.js has <a href="https://nodejs.org/api/process.html#process_event_uncaughtexception"><code>process.on("uncaughtException")</code></a> for that. And in the browser we can assign a function to the special <a href="mdn:api/GlobalEventHandlers/onerror">window.onerror</a> property, that will run in case of an uncaught error.</p>
<p>The syntax:</p>
<div class="sourceCode" id="cb14"><pre class="sourceCode js"><code class="sourceCode javascript"><a class="sourceLine" id="cb14-1" title="1"><span class="va">window</span>.<span class="at">onerror</span> <span class="op">=</span> <span class="kw">function</span>(message<span class="op">,</span> url<span class="op">,</span> line<span class="op">,</span> col<span class="op">,</span> error) <span class="op">{</span></a>
<a class="sourceLine" id="cb14-2" title="2">  <span class="co">// ...</span></a>
<a class="sourceLine" id="cb14-3" title="3"><span class="op">};</span></a></code></pre></div>
<dl>
<dt><code>message</code></dt>
<dd>Error message.
</dd>
<dt><code>url</code></dt>
<dd>URL of the script where error happened.
</dd>
<dt><code>line</code>, <code>col</code></dt>
<dd>Line and column numbers where error happened.
</dd>
<dt><code>error</code></dt>
<dd>Error object.
</dd>
</dl>
<p>For instance:</p>
<p>``<code>html run untrusted refresh height=1 &lt;script&gt; *!*   window.onerror = function(message, url, line, col, error) {     alert(</code>${message}At <span class="math inline"><em>l</em><em>i</em><em>n</em><em>e</em>:</span>{col} of ${url}`); }; <em>/!</em></p>
<p>function readData() { badFunc(); // Whoops, something went wrong! }</p>
readData();
</script>
<p>```</p>
<p>The role of the global handler <code>window.onerror</code> is usually not to recover the script execution – that’s probably impossible in case of programming errors, but to send the error message to developers.</p>
<p>There are also web-services that provide error-logging for such cases, like <a href="https://errorception.com" class="uri">https://errorception.com</a> or <a href="http://www.muscula.com" class="uri">http://www.muscula.com</a>.</p>
<p>They work like this:</p>
<ol type="1">
<li>We register at the service and get a piece of JS (or a script URL) from them to insert on pages.</li>
<li>That JS script sets a custom <code>window.onerror</code> function.</li>
<li>When an error occurs, it sends a network request about it to the service.</li>
<li>We can log in to the service web interface and see errors.</li>
</ol>
<h2 id="summary">Summary</h2>
<p>The <code>try...catch</code> construct allows to handle runtime errors. It literally allows to “try” running the code and “catch” errors that may occur in it.</p>
<p>The syntax is:</p>
<div class="sourceCode" id="cb15"><pre class="sourceCode js"><code class="sourceCode javascript"><a class="sourceLine" id="cb15-1" title="1"><span class="cf">try</span> <span class="op">{</span></a>
<a class="sourceLine" id="cb15-2" title="2">  <span class="co">// run this code</span></a>
<a class="sourceLine" id="cb15-3" title="3"><span class="op">}</span> <span class="cf">catch</span> (err) <span class="op">{</span></a>
<a class="sourceLine" id="cb15-4" title="4">  <span class="co">// if an error happened, then jump here</span></a>
<a class="sourceLine" id="cb15-5" title="5">  <span class="co">// err is the error object</span></a>
<a class="sourceLine" id="cb15-6" title="6"><span class="op">}</span> <span class="cf">finally</span> <span class="op">{</span></a>
<a class="sourceLine" id="cb15-7" title="7">  <span class="co">// do in any case after try/catch</span></a>
<a class="sourceLine" id="cb15-8" title="8"><span class="op">}</span></a></code></pre></div>
<p>There may be no <code>catch</code> section or no <code>finally</code>, so shorter constructs <code>try...catch</code> and <code>try...finally</code> are also valid.</p>
<p>Error objects have following properties:</p>
<ul>
<li><code>message</code> – the human-readable error message.</li>
<li><code>name</code> – the string with error name (error constructor name).</li>
<li><code>stack</code> (non-standard, but well-supported) – the stack at the moment of error creation.</li>
</ul>
<p>If an error object is not needed, we can omit it by using <code>catch {</code> instead of <code>catch (err) {</code>.</p>
<p>We can also generate our own errors using the <code>throw</code> operator. Technically, the argument of <code>throw</code> can be anything, but usually it’s an error object inheriting from the built-in <code>Error</code> class. More on extending errors in the next chapter.</p>
<p><em>Rethrowing</em> is a very important pattern of error handling: a <code>catch</code> block usually expects and knows how to handle the particular error type, so it should rethrow errors it doesn’t know.</p>
<p>Even if we don’t have <code>try...catch</code>, most environments allow us to setup a “global” error handler to catch errors that “fall out”. In-browser, that’s <code>window.onerror</code>.</p>
</body>
</html>
